[2025-03-13T05:50:01.824+0000] {local_task_job_runner.py:123} INFO - ::group::Pre task execution logs
[2025-03-13T05:50:01.875+0000] {taskinstance.py:2614} INFO - Dependencies all met for dep_context=non-requeueable deps ti=<TaskInstance: data_prep_transformation.data_validation manual__2025-03-13T05:47:39.846529+00:00 [queued]>
[2025-03-13T05:50:01.911+0000] {taskinstance.py:2614} INFO - Dependencies all met for dep_context=requeueable deps ti=<TaskInstance: data_prep_transformation.data_validation manual__2025-03-13T05:47:39.846529+00:00 [queued]>
[2025-03-13T05:50:01.913+0000] {taskinstance.py:2867} INFO - Starting attempt 2 of 2
[2025-03-13T05:50:02.005+0000] {taskinstance.py:2890} INFO - Executing <Task(_PythonDecoratedOperator): data_validation> on 2025-03-13 05:47:39.846529+00:00
[2025-03-13T05:50:02.049+0000] {logging_mixin.py:190} WARNING - /home/airflow/.local/lib/python3.12/site-packages/airflow/task/task_runner/standard_task_runner.py:70 DeprecationWarning: This process (pid=648) is multi-threaded, use of fork() may lead to deadlocks in the child.
[2025-03-13T05:50:02.051+0000] {standard_task_runner.py:72} INFO - Started process 666 to run task
[2025-03-13T05:50:02.069+0000] {standard_task_runner.py:104} INFO - Running: ['airflow', 'tasks', 'run', 'data_prep_transformation', 'data_validation', 'manual__2025-03-13T05:47:39.846529+00:00', '--job-id', '227', '--raw', '--subdir', 'DAGS_FOLDER/data_prep_transformation.py', '--cfg-path', '/tmp/tmpygix0blj']
[2025-03-13T05:50:02.087+0000] {standard_task_runner.py:105} INFO - Job 227: Subtask data_validation
[2025-03-13T05:50:02.378+0000] {task_command.py:467} INFO - Running <TaskInstance: data_prep_transformation.data_validation manual__2025-03-13T05:47:39.846529+00:00 [running]> on host 07407d10f364
[2025-03-13T05:50:03.161+0000] {taskinstance.py:3134} INFO - Exporting env vars: AIRFLOW_CTX_DAG_OWNER='airflow' AIRFLOW_CTX_DAG_ID='data_prep_transformation' AIRFLOW_CTX_TASK_ID='data_validation' AIRFLOW_CTX_EXECUTION_DATE='2025-03-13T05:47:39.846529+00:00' AIRFLOW_CTX_TRY_NUMBER='2' AIRFLOW_CTX_DAG_RUN_ID='manual__2025-03-13T05:47:39.846529+00:00'
[2025-03-13T05:50:03.184+0000] {taskinstance.py:732} INFO - ::endgroup::
[2025-03-13T05:50:03.918+0000] {context_factory.py:385} INFO - Could not find local file-backed GX project
[2025-03-13T05:50:03.964+0000] {base.py:1507} INFO - Created temporary directory '/tmp/tmpc3yshqp6' for ephemeral docs site
[2025-03-13T05:50:04.087+0000] {config.py:191} INFO - Loading 'datasources' ->
[]
[2025-03-13T05:50:04.641+0000] {taskinstance.py:3313} ERROR - Task failed with exception
Traceback (most recent call last):
  File "/home/airflow/.local/lib/python3.12/site-packages/great_expectations/datasource/datasource_dict.py", line 104, in _get_ds_from_store
    return self._datasource_store.retrieve_by_name(name)
           ^^^^^^^^^^^^^^^^^^^^^^^^^^^^^^^^^^^^^^^^^^^^^
  File "/home/airflow/.local/lib/python3.12/site-packages/great_expectations/data_context/store/datasource_store.py", line 168, in retrieve_by_name
    raise ValueError(  # noqa: TRY003 # FIXME CoP
ValueError: Unable to load datasource `/opt/data/telco-customer-churn-mul-sources.csv` -- no configuration found or invalid configuration.

During handling of the above exception, another exception occurred:

Traceback (most recent call last):
  File "/home/airflow/.local/lib/python3.12/site-packages/airflow/models/taskinstance.py", line 768, in _execute_task
    result = _execute_callable(context=context, **execute_callable_kwargs)
             ^^^^^^^^^^^^^^^^^^^^^^^^^^^^^^^^^^^^^^^^^^^^^^^^^^^^^^^^^^^^^
  File "/home/airflow/.local/lib/python3.12/site-packages/airflow/models/taskinstance.py", line 734, in _execute_callable
    return ExecutionCallableRunner(
           ^^^^^^^^^^^^^^^^^^^^^^^^
  File "/home/airflow/.local/lib/python3.12/site-packages/airflow/utils/operator_helpers.py", line 252, in run
    return self.func(*args, **kwargs)
           ^^^^^^^^^^^^^^^^^^^^^^^^^^
  File "/home/airflow/.local/lib/python3.12/site-packages/airflow/models/baseoperator.py", line 424, in wrapper
    return func(self, *args, **kwargs)
           ^^^^^^^^^^^^^^^^^^^^^^^^^^^
  File "/home/airflow/.local/lib/python3.12/site-packages/airflow/decorators/base.py", line 266, in execute
    return_value = super().execute(context)
                   ^^^^^^^^^^^^^^^^^^^^^^^^
  File "/home/airflow/.local/lib/python3.12/site-packages/airflow/models/baseoperator.py", line 424, in wrapper
    return func(self, *args, **kwargs)
           ^^^^^^^^^^^^^^^^^^^^^^^^^^^
  File "/home/airflow/.local/lib/python3.12/site-packages/airflow/operators/python.py", line 238, in execute
    return_value = self.execute_callable()
                   ^^^^^^^^^^^^^^^^^^^^^^^
  File "/home/airflow/.local/lib/python3.12/site-packages/airflow/operators/python.py", line 256, in execute_callable
    return runner.run(*self.op_args, **self.op_kwargs)
           ^^^^^^^^^^^^^^^^^^^^^^^^^^^^^^^^^^^^^^^^^^^
  File "/home/airflow/.local/lib/python3.12/site-packages/airflow/utils/operator_helpers.py", line 252, in run
    return self.func(*args, **kwargs)
           ^^^^^^^^^^^^^^^^^^^^^^^^^^
  File "/opt/airflow/dags/data_prep_transformation.py", line 28, in data_validation
    ge_df = context.data_sources.get(DATA_PATH)
            ^^^^^^^^^^^^^^^^^^^^^^^^^^^^^^^^^^^
  File "/home/airflow/.local/lib/python3.12/site-packages/great_expectations/datasource/fluent/sources.py", line 629, in get
    return self.all()[name]
           ~~~~~~~~~~^^^^^^
  File "/home/airflow/.local/lib/python3.12/site-packages/great_expectations/datasource/datasource_dict.py", line 197, in __getitem__
    ds = super().__getitem__(name)
         ^^^^^^^^^^^^^^^^^^^^^^^^^
  File "/home/airflow/.local/lib/python3.12/site-packages/great_expectations/datasource/datasource_dict.py", line 115, in __getitem__
    ds = self._get_ds_from_store(name)
         ^^^^^^^^^^^^^^^^^^^^^^^^^^^^^
  File "/home/airflow/.local/lib/python3.12/site-packages/great_expectations/datasource/datasource_dict.py", line 106, in _get_ds_from_store
    raise KeyError(f"Could not find a datasource named '{name}'")  # noqa: TRY003 # FIXME CoP
    ^^^^^^^^^^^^^^^^^^^^^^^^^^^^^^^^^^^^^^^^^^^^^^^^^^^^^^^^^^^^^
KeyError: "Could not find a datasource named '/opt/data/telco-customer-churn-mul-sources.csv'"
[2025-03-13T05:50:04.727+0000] {taskinstance.py:1226} INFO - Marking task as FAILED. dag_id=data_prep_transformation, task_id=data_validation, run_id=manual__2025-03-13T05:47:39.846529+00:00, execution_date=20250313T054739, start_date=20250313T055001, end_date=20250313T055004
[2025-03-13T05:50:04.954+0000] {taskinstance.py:341} INFO - ::group::Post task execution logs
[2025-03-13T05:50:04.963+0000] {standard_task_runner.py:124} ERROR - Failed to execute job 227 for task data_validation ("Could not find a datasource named '/opt/data/telco-customer-churn-mul-sources.csv'"; 666)
Traceback (most recent call last):
  File "/home/airflow/.local/lib/python3.12/site-packages/great_expectations/datasource/datasource_dict.py", line 104, in _get_ds_from_store
    return self._datasource_store.retrieve_by_name(name)
           ^^^^^^^^^^^^^^^^^^^^^^^^^^^^^^^^^^^^^^^^^^^^^
  File "/home/airflow/.local/lib/python3.12/site-packages/great_expectations/data_context/store/datasource_store.py", line 168, in retrieve_by_name
    raise ValueError(  # noqa: TRY003 # FIXME CoP
ValueError: Unable to load datasource `/opt/data/telco-customer-churn-mul-sources.csv` -- no configuration found or invalid configuration.

During handling of the above exception, another exception occurred:

Traceback (most recent call last):
  File "/home/airflow/.local/lib/python3.12/site-packages/airflow/task/task_runner/standard_task_runner.py", line 117, in _start_by_fork
    ret = args.func(args, dag=self.dag)
          ^^^^^^^^^^^^^^^^^^^^^^^^^^^^^
  File "/home/airflow/.local/lib/python3.12/site-packages/airflow/cli/cli_config.py", line 49, in command
    return func(*args, **kwargs)
           ^^^^^^^^^^^^^^^^^^^^^
  File "/home/airflow/.local/lib/python3.12/site-packages/airflow/utils/cli.py", line 116, in wrapper
    return f(*args, **kwargs)
           ^^^^^^^^^^^^^^^^^^
  File "/home/airflow/.local/lib/python3.12/site-packages/airflow/cli/commands/task_command.py", line 483, in task_run
    task_return_code = _run_task_by_selected_method(args, _dag, ti)
                       ^^^^^^^^^^^^^^^^^^^^^^^^^^^^^^^^^^^^^^^^^^^^
  File "/home/airflow/.local/lib/python3.12/site-packages/airflow/cli/commands/task_command.py", line 256, in _run_task_by_selected_method
    return _run_raw_task(args, ti)
           ^^^^^^^^^^^^^^^^^^^^^^^
  File "/home/airflow/.local/lib/python3.12/site-packages/airflow/cli/commands/task_command.py", line 341, in _run_raw_task
    return ti._run_raw_task(
           ^^^^^^^^^^^^^^^^^
  File "/home/airflow/.local/lib/python3.12/site-packages/airflow/utils/session.py", line 97, in wrapper
    return func(*args, session=session, **kwargs)
           ^^^^^^^^^^^^^^^^^^^^^^^^^^^^^^^^^^^^^^
  File "/home/airflow/.local/lib/python3.12/site-packages/airflow/models/taskinstance.py", line 3006, in _run_raw_task
    return _run_raw_task(
           ^^^^^^^^^^^^^^
  File "/home/airflow/.local/lib/python3.12/site-packages/airflow/models/taskinstance.py", line 274, in _run_raw_task
    TaskInstance._execute_task_with_callbacks(
  File "/home/airflow/.local/lib/python3.12/site-packages/airflow/models/taskinstance.py", line 3161, in _execute_task_with_callbacks
    result = self._execute_task(context, task_orig)
             ^^^^^^^^^^^^^^^^^^^^^^^^^^^^^^^^^^^^^^
  File "/home/airflow/.local/lib/python3.12/site-packages/airflow/models/taskinstance.py", line 3185, in _execute_task
    return _execute_task(self, context, task_orig)
           ^^^^^^^^^^^^^^^^^^^^^^^^^^^^^^^^^^^^^^^
  File "/home/airflow/.local/lib/python3.12/site-packages/airflow/models/taskinstance.py", line 768, in _execute_task
    result = _execute_callable(context=context, **execute_callable_kwargs)
             ^^^^^^^^^^^^^^^^^^^^^^^^^^^^^^^^^^^^^^^^^^^^^^^^^^^^^^^^^^^^^
  File "/home/airflow/.local/lib/python3.12/site-packages/airflow/models/taskinstance.py", line 734, in _execute_callable
    return ExecutionCallableRunner(
           ^^^^^^^^^^^^^^^^^^^^^^^^
  File "/home/airflow/.local/lib/python3.12/site-packages/airflow/utils/operator_helpers.py", line 252, in run
    return self.func(*args, **kwargs)
           ^^^^^^^^^^^^^^^^^^^^^^^^^^
  File "/home/airflow/.local/lib/python3.12/site-packages/airflow/models/baseoperator.py", line 424, in wrapper
    return func(self, *args, **kwargs)
           ^^^^^^^^^^^^^^^^^^^^^^^^^^^
  File "/home/airflow/.local/lib/python3.12/site-packages/airflow/decorators/base.py", line 266, in execute
    return_value = super().execute(context)
                   ^^^^^^^^^^^^^^^^^^^^^^^^
  File "/home/airflow/.local/lib/python3.12/site-packages/airflow/models/baseoperator.py", line 424, in wrapper
    return func(self, *args, **kwargs)
           ^^^^^^^^^^^^^^^^^^^^^^^^^^^
  File "/home/airflow/.local/lib/python3.12/site-packages/airflow/operators/python.py", line 238, in execute
    return_value = self.execute_callable()
                   ^^^^^^^^^^^^^^^^^^^^^^^
  File "/home/airflow/.local/lib/python3.12/site-packages/airflow/operators/python.py", line 256, in execute_callable
    return runner.run(*self.op_args, **self.op_kwargs)
           ^^^^^^^^^^^^^^^^^^^^^^^^^^^^^^^^^^^^^^^^^^^
  File "/home/airflow/.local/lib/python3.12/site-packages/airflow/utils/operator_helpers.py", line 252, in run
    return self.func(*args, **kwargs)
           ^^^^^^^^^^^^^^^^^^^^^^^^^^
  File "/opt/airflow/dags/data_prep_transformation.py", line 28, in data_validation
    ge_df = context.data_sources.get(DATA_PATH)
            ^^^^^^^^^^^^^^^^^^^^^^^^^^^^^^^^^^^
  File "/home/airflow/.local/lib/python3.12/site-packages/great_expectations/datasource/fluent/sources.py", line 629, in get
    return self.all()[name]
           ~~~~~~~~~~^^^^^^
  File "/home/airflow/.local/lib/python3.12/site-packages/great_expectations/datasource/datasource_dict.py", line 197, in __getitem__
    ds = super().__getitem__(name)
         ^^^^^^^^^^^^^^^^^^^^^^^^^
  File "/home/airflow/.local/lib/python3.12/site-packages/great_expectations/datasource/datasource_dict.py", line 115, in __getitem__
    ds = self._get_ds_from_store(name)
         ^^^^^^^^^^^^^^^^^^^^^^^^^^^^^
  File "/home/airflow/.local/lib/python3.12/site-packages/great_expectations/datasource/datasource_dict.py", line 106, in _get_ds_from_store
    raise KeyError(f"Could not find a datasource named '{name}'")  # noqa: TRY003 # FIXME CoP
    ^^^^^^^^^^^^^^^^^^^^^^^^^^^^^^^^^^^^^^^^^^^^^^^^^^^^^^^^^^^^^
KeyError: "Could not find a datasource named '/opt/data/telco-customer-churn-mul-sources.csv'"
[2025-03-13T05:50:05.008+0000] {local_task_job_runner.py:266} INFO - Task exited with return code 1
[2025-03-13T05:50:05.106+0000] {taskinstance.py:3901} INFO - 0 downstream tasks scheduled from follow-on schedule check
[2025-03-13T05:50:05.148+0000] {local_task_job_runner.py:245} INFO - ::endgroup::
